Workbook

Sheet calendario 2021
H1: INFORME SEMANAL | R1: =TODAY() -> 46139
A2: CORTES | H2: PROGRAMACION 2021 | R2: versión 0.0
A4: desde | C4: hasta | E4: largo | F4: # week | H4: ENERO | P4: FECHA INFORME | Q4: DETALLES | R4: FERIADO
A5: m | B5: d | C5: m | D5: d | H5: L | I5: M | J5: M | K5: J | L5: V | M5: S | N5: D
F6: 52 | I6: =+J6-1 -> 43830 | J6: 43831 | L6: =1+K6 -> 1 | M6: =1+L6 -> 2 | N6: =1+M6 -> 3 | R6: Viernes 1 de Enero: Año Nuevo
A7: 12 | B7: 31 | C7: =+MONTH(K7) -> 1 | D7: =+DAY(K7) -> 7 | E7: =IF(A7=C7,D7-B7+1,DAY(EOMONTH(I7,0))-B7+D7+1) -> 8 | F7: 1 | H7: =1+N6 -> 4 | I7: =1+H7 -> 5 | J7: =1+I7 -> 6 | K7: =1+J7 -> 7 | L7: =1+K7 -> 8 | M7: =1+L7 -> 9 | N7: =1+M7 -> 10 | P7: =DATE(2021,C7,D7+1) -> 44204 | Q7: =IF(A7=C7,"Informe "&D7-B7+1&" días ( "&D7-B7&" reales y 1 proyectado); Reales del "&B7&"/"&C7&" al "&D7-1&"/"&A7&" ,Proyectado "&D7&"/"&A7,"Informe "&DAY(EOMONTH(K6,0))-B7+D7+1&" días ( "&DAY(EOMONTH(K6,0))-B7+D7&" reales y 1 proyectado); Reales del "&B7&"/"&A7&" al "&D7-1&"/"&C7&" ,Proyectado "&D7&"/"&C7) -> Informe 8 días ( 7 reales y 1 proyectado); Reales del 31/12 al 6/1 ,Proyectado 7/1
A8: =+MONTH(L7) -> 1 | B8: =+DAY(L7) -> 8 | C8: =+MONTH(K8) -> 1 | D8: =+DAY(K8) -> 14 | E8: =IF(A8=C8,D8-B8+1,DAY(EOMONTH(I8,0))-B8+D8+1) -> 7 | F8: 2 | H8: =1+N7 -> 11 | I8: =1+H8 -> 12 | J8: =1+I8 -> 13 | K8: =1+J8 -> 14 | L8: =1+K8 -> 15 | M8: =1+L8 -> 16 | N8: =1+M8 -> 17 | P8: =DATE(2021,C8,D8+1) -> 44211 | Q8: =IF(A8=C8,"Informe "&D8-B8+1&" días ( "&D8-B8&" reales y 1 proyectado); Reales del "&B8&"/"&C8&" al "&D8-1&"/"&A8&" ,Proyectado "&D8&"/"&A8,"Informe "&DAY(EOMONTH(K8,0))-B8+D8+1&" días ( "&DAY(EOMONTH(K8,0))-B8+D8&" reales y 1 proyectado); Reales del "&B8&"/"&A8&" al "&D8-1&"/"&C8&" ,Proyectado "&D8&"/"&C8) -> Informe 7 días ( 6 reales y 1 proyectado); Reales del 8/1 al 13/1 ,Proyectado 14/1
A9: =+MONTH(L8) -> 1 | B9: =+DAY(L8) -> 15 | C9: =+MONTH(K9) -> 1 | D9: =+DAY(K9) -> 21 | E9: =IF(A9=C9,D9-B9+1,DAY(EOMONTH(I9,0))-B9+D9+1) -> 7 | F9: 3 | H9: =1+N8 -> 18 | I9: =1+H9 -> 19 | J9: =1+I9 -> 20 | K9: =1+J9 -> 21 | L9: =1+K9 -> 22 | M9: =1+L9 -> 23 | N9: =1+M9 -> 24 | P9: =DATE(2021,C9,D9+1) -> 44218 | Q9: =IF(A9=C9,"Informe "&D9-B9+1&" días ( "&D9-B9&" reales y 1 proyectado); Reales del "&B9&"/"&C9&" al "&D9-1&"/"&A9&" ,Proyectado "&D9&"/"&A9,"Informe "&DAY(EOMONTH(K9,0))-B9+D9+1&" días ( "&DAY(EOMONTH(K9,0))-B9+D9&" reales y 1 proyectado); Reales del "&B9&"/"&A9&" al "&D9-1&"/"&C9&" ,Proyectado "&D9&"/"&C9) -> Informe 7 días ( 6 reales y 1 proyectado); Reales del 15/1 al 20/1 ,Proyectado 21/1
A10: =+MONTH(L9) -> 1 | B10: =+DAY(L9) -> 22 | C10: =+MONTH(K10) -> 1 | D10: =+DAY(K10) -> 28 | E10: =IF(A10=C10,D10-B10+1,DAY(EOMONTH(I10,0))-B10+D10+1) -> 7 | F10: 4 | H10: =1+N9 -> 25 | I10: =1+H10 -> 26 | J10: =1+I10 -> 27 | K10: =1+J10 -> 28 | L10: =1+K10 -> 29 | M10: =1+L10 -> 30 | N10: =1+M10 -> 31 | P10: =DATE(2021,C10,D10+1) -> 44225 | Q10: =IF(A10=C10,"Informe "&D10-B10+1&" días ( "&D10-B10&" reales y 1 proyectado); Reales del "&B10&"/"&C10&" al "&D10-1&"/"&A10&" ,Proyectado "&D10&"/"&A10,"Informe "&DAY(EOMONTH(K10,0))-B10+D10+1&" días ( "&DAY(EOMONTH(K10,0))-B10+D10&" reales y 1 proyectado); Reales del "&B10&"/"&A10&" al "&D10-1&"/"&C10&" ,Proyectado "&D10&"/"&C10) -> Informe 7 días ( 6 reales y 1 proyectado); Reales del 22/1 al 27/1 ,Proyectado 28/1
A12: desde | C12: hasta | E12: largo | F12: # week | H12: FEBRERO | P12: FECHA INFORME | Q12: DETALLES | R12: FERIADO
A13: m | B13: d | C13: m | D13: d | H13: L | I13: M | J13: M | K13: J | L13: V | M13: S | N13: D
A14: =+MONTH(L10) -> 1 | B14: =+DAY(L10) -> 29 | C14: =+MONTH(K14) -> 2 | D14: =+DAY(K14) -> 4 | E14: =IF(A14=C14,D14-B14+1,DAY(EOMONTH(I10,0))-B14+D14+1) -> 7 | F14: 5 | H14: =1+N10 -> 32 | I14: =+H14+1 -> 33 | J14: =+I14+1 -> 34 | K14: =+J14+1 -> 35 | L14: =+K14+1 -> 36 | M14: =+L14+1 -> 37 | N14: =+M14+1 -> 38 | P14: =DATE(2021,C14,D14+1) -> 44232 | Q14: =IF(A14=C14,"Informe "&D14-B14+1&" días ( "&D14-B14&" reales y 1 proyectado); Reales del "&B14&"/"&C14&" al "&D14-1&"/"&A14&" ,Proyectado "&D14&"/"&A14,"Informe "&DAY(EOMONTH(K10,0))-B14+D14+1&" días ( "&DAY(EOMONTH(K10,0))-B14+D14&" reales y 1 proyectado); Reales del "&B14&"/"&A14&" al "&D14-1&"/"&C14&" ,Proyectado "&D14&"/"&C14) -> Informe 7 días ( 6 reales y 1 proyectado); Reales del 29/1 al 3/2 ,Proyectado 4/2
A15: =+MONTH(L14) -> 2 | B15: =+DAY(L14) -> 5 | C15: =+MONTH(K15) -> 2 | D15: =+DAY(K15) -> 11 | E15: =IF(A15=C15,D15-B15+1,DAY(EOMONTH(I15,0))-B15+D15+1) -> 7 | F15: =1+F14 -> 6 | H15: =1+N14 -> 39 | I15: =+H15+1 -> 40 | J15: =+I15+1 -> 41 | K15: =+J15+1 -> 42 | L15: =+K15+1 -> 43 | M15: =+L15+1 -> 44 | N15: =+M15+1 -> 45 | P15: =DATE(2021,C15,D15+1) -> 44239 | Q15: =IF(A15=C15,"Informe "&D15-B15+1&" días ( "&D15-B15&" reales y 1 proyectado); Reales del "&B15&"/"&C15&" al "&D15-1&"/"&A15&" ,Proyectado "&D15&"/"&A15,"Informe "&DAY(EOMONTH(K15,0))-B15+D15+1&" días ( "&DAY(EOMONTH(K15,0))-B15+D15&" reales y 1 proyectado); Reales del "&B15&"/"&A15&" al "&D15-1&"/"&C15&" ,Proyectado "&D15&"/"&C15) -> Informe 7 días ( 6 reales y 1 proyectado); Reales del 5/2 al 10/2 ,Proyectado 11/2
A16: =+MONTH(L15) -> 2 | B16: =+DAY(L15) -> 12 | C16: =+MONTH(K16) -> 2 | D16: =+DAY(K16) -> 18 | E16: =IF(A16=C16,D16-B16+1,DAY(EOMONTH(I16,0))-B16+D16+1) -> 7 | F16: =1+F15 -> 7 | H16: =1+N15 -> 46 | I16: =+H16+1 -> 47 | J16: =+I16+1 -> 48 | K16: =+J16+1 -> 49 | L16: =+K16+1 -> 50 | M16: =+L16+1 -> 51 | N16: =+M16+1 -> 52 | P16: =DATE(2021,C16,D16+1) -> 44246 | Q16: =IF(A16=C16,"Informe "&D16-B16+1&" días ( "&D16-B16&" reales y 1 proyectado); Reales del "&B16&"/"&C16&" al "&D16-1&"/"&A16&" ,Proyectado "&D16&"/"&A16,"Informe "&DAY(EOMONTH(K16,0))-B16+D16+1&" días ( "&DAY(EOMONTH(K16,0))-B16+D16&" reales y 1 proyectado); Reales del "&B16&"/"&A16&" al "&D16-1&"/"&C16&" ,Proyectado "&D16&"/"&C16) -> Informe 7 días ( 6 reales y 1 proyectado); Reales del 12/2 al 17/2 ,Proyectado 18/2
A17: =+MONTH(L16) -> 2 | B17: =+DAY(L16) -> 19 | C17: =+MONTH(K17) -> 2 | D17: =+DAY(K17) -> 25 | E17: =IF(A17=C17,D17-B17+1,DAY(EOMONTH(I16,0))-B17+D17+1) -> 7 | F17: =1+F16 -> 8 | H17: =1+N16 -> 53 | I17: =+H17+1 -> 54 | J17: =+I17+1 -> 55 | K17: =+J17+1 -> 56 | L17: =+K17+1 -> 57 | M17: =+L17+1 -> 58 | N17: =+M17+1 -> 59 | P17: =DATE(2021,C17,D17+1) -> 44253 | Q17: =IF(A17=C17,"Informe "&D17-B17+1&" días ( "&D17-B17&" reales y 1 proyectado); Reales del "&B17&"/"&C17&" al "&D17-1&"/"&A17&" ,Proyectado "&D17&"/"&A17,"Informe "&DAY(EOMONTH(K17,0))-B17+D17+1&" días ( "&DAY(EOMONTH(K17,0))-B17+D17&" reales y 1 proyectado); Reales del "&B17&"/"&A17&" al "&D17-1&"/"&C17&" ,Proyectado "&D17&"/"&C17) -> Informe 7 días ( 6 reales y 1 proyectado); Reales del 19/2 al 24/2 ,Proyectado 25/2
A19: desde | C19: hasta | E19: largo | F19: # week | H19: MARZO | P19: FECHA INFORME | Q19: DETALLES | R19: FERIADO
A20: m | B20: d | C20: m | D20: d | H20: L | I20: M | J20: M | K20: J | L20: V | M20: S | N20: D
A21: =+MONTH(L17) -> 2 | B21: =+DAY(L17) -> 26 | C21: =+MONTH(K21) -> 3 | D21: =+DAY(K21) -> 4 | E21: =IF(A21=C21,D21-B21+1,DAY(EOMONTH(I17,0))-B21+D21+1) -> 7 | F21: =F17+1 -> 9 | H21: 44256 | I21: =+H21+1 -> 44257 | J21: =+I21+1 -> 44258 | K21: =+J21+1 -> 44259 | L21: =+K21+1 -> 44260 | M21: =+L21+1 -> 44261 | N21: =+M21+1 -> 44262 | P21: =DATE(2021,C21,D21+1) -> 44260 | Q21: =IF(A21=C21,"Informe "&D21-B21+1&" días ( "&D21-B21&" reales y 1 proyectado); Reales del "&B21&"/"&C21&" al "&D21-1&"/"&A21&" ,Proyectado "&D21&"/"&A21,"Informe "&DAY(EOMONTH(K17,0))-B21+D21+1&" días ( "&DAY(EOMONTH(K17,0))-B21+D21&" reales y 1 proyectado); Reales del "&B21&"/"&A21&" al "&D21-1&"/"&C21&" ,Proyectado "&D21&"/"&C21) -> Informe 7 días ( 6 reales y 1 proyectado); Reales del 26/2 al 3/3 ,Proyectado 4/3
A22: =+MONTH(L21) -> 3 | B22: =+DAY(L21) -> 5 | C22: =+MONTH(K22) -> 3 | D22: =+DAY(K22) -> 11 | E22: =IF(A22=C22,D22-B22+1,DAY(EOMONTH(I22,0))-B22+D22+1) -> 7 | F22: =1+F21 -> 10 | H22: =1+N21 -> 44263 | I22: =+H22+1 -> 44264 | J22: =+I22+1 -> 44265 | K22: =+J22+1 -> 44266 | L22: =+K22+1 -> 44267 | M22: =+L22+1 -> 44268 | N22: =+M22+1 -> 44269 | P22: =DATE(2021,C22,D22+1) -> 44267 | Q22: =IF(A22=C22,"Informe "&D22-B22+1&" días ( "&D22-B22&" reales y 1 proyectado); Reales del "&B22&"/"&C22&" al "&D22-1&"/"&A22&" ,Proyectado "&D22&"/"&A22,"Informe "&DAY(EOMONTH(K22,0))-B22+D22+1&" días ( "&DAY(EOMONTH(K22,0))-B22+D22&" reales y 1 proyectado); Reales del "&B22&"/"&A22&" al "&D22-1&"/"&C22&" ,Proyectado "&D22&"/"&C22) -> Informe 7 días ( 6 reales y 1 proyectado); Reales del 5/3 al 10/3 ,Proyectado 11/3
A23: =+MONTH(L22) -> 3 | B23: =+DAY(L22) -> 12 | C23: =+MONTH(K23) -> 3 | D23: =+DAY(K23) -> 18 | E23: =IF(A23=C23,D23-B23+1,DAY(EOMONTH(I23,0))-B23+D23+1) -> 7 | F23: =1+F22 -> 11 | H23: =1+N22 -> 44270 | I23: =+H23+1 -> 44271 | J23: =+I23+1 -> 44272 | K23: =+J23+1 -> 44273 | L23: =+K23+1 -> 44274 | M23: =+L23+1 -> 44275 | N23: =+M23+1 -> 44276 | P23: =DATE(2021,C23,D23+1) -> 44274 | Q23: =IF(A23=C23,"Informe "&D23-B23+1&" días ( "&D23-B23&" reales y 1 proyectado); Reales del "&B23&"/"&C23&" al "&D23-1&"/"&A23&" ,Proyectado "&D23&"/"&A23,"Informe "&DAY(EOMONTH(K23,0))-B23+D23+1&" días ( "&DAY(EOMONTH(K23,0))-B23+D23&" reales y 1 proyectado); Reales del "&B23&"/"&A23&" al "&D23-1&"/"&C23&" ,Proyectado "&D23&"/"&C23) -> Informe 7 días ( 6 reales y 1 proyectado); Reales del 12/3 al 17/3 ,Proyectado 18/3
A24: =+MONTH(L23) -> 3 | B24: =+DAY(L23) -> 19 | C24: =+MONTH(K24) -> 3 | D24: =+DAY(K24) -> 25 | E24: =IF(A24=C24,D24-B24+1,DAY(EOMONTH(I23,0))-B24+D24+1) -> 7 | F24: =1+F23 -> 12 | H24: =1+N23 -> 44277 | I24: =+H24+1 -> 44278 | J24: =+I24+1 -> 44279 | K24: =+J24+1 -> 44280 | L24: =+K24+1 -> 44281 | M24: =+L24+1 -> 44282 | N24: =+M24+1 -> 44283 | P24: =DATE(2021,C24,D24+1) -> 44281 | Q24: =IF(A24=C24,"Informe "&D24-B24+1&" días ( "&D24-B24&" reales y 1 proyectado); Reales del "&B24&"/"&C24&" al "&D24-1&"/"&A24&" ,Proyectado "&D24&"/"&A24,"Informe "&DAY(EOMONTH(K24,0))-B24+D24+1&" días ( "&DAY(EOMONTH(K24,0))-B24+D24&" reales y 1 proyectado); Reales del "&B24&"/"&A24&" al "&D24-1&"/"&C24&" ,Proyectado "&D24&"/"&C24) -> Informe 7 días ( 6 reales y 1 proyectado); Reales del 19/3 al 24/3 ,Proyectado 25/3
H25: =1+N24 -> 44284 | I25: =+H25+1 -> 44285 | J25: =+I25+1 -> 44286
A28: desde | C28: hasta | E28: largo | F28: # week | H28: ABRIL | P28: FECHA INFORME | Q28: DETALLES | R28: FERIADO
A29: m | B29: d | C29: m | D29: d | H29: L | I29: M | J29: M | K29: J | L29: V | M29: S | N29: D
A30: =+MONTH(L24) -> 3 | B30: =+DAY(L24) -> 26 | C30: =+MONTH(J25) -> 3 | D30: =+DAY(J25) -> 31 | E30: =IF(A30=C30,D30-B30+1,DAY(EOMONTH(I24,0))-B30+D30+1) -> 6 | F30: =F24+1 -> 13 | K30: =+J25+1 -> 44287 | L30: =+K30+1 -> 44288 | M30: =+L30+1 -> 44289 | N30: =+M30+1 -> 44290 | P30: =DATE(2021,C30,D30+1) -> 44287 | Q30: =IF(A30=C30,"Informe "&D30-B30+1&" días ( "&D30-B30&" reales y 1 proyectado); Reales del "&B30&"/"&C30&" al "&D30-1&"/"&A30&" ,Proyectado "&D30&"/"&A30,"Informe "&DAY(EOMONTH(K24,0))-B30+D30+1&" días ( "&DAY(EOMONTH(K24,0))-B30+D30&" reales y 1 proyectado); Reales del "&B30&"/"&A30&" al "&D30-1&"/"&C30&" ,Proyectado "&D30&"/"&C30) -> Informe 6 días ( 5 reales y 1 proyectado); Reales del 26/3 al 30/3 ,Proyectado 31/3 | R30: Viernes 02 de Abril: Viernes Santo
A31: =+MONTH(K30) -> 4 | B31: =+DAY(K30) -> 1 | C31: =+MONTH(K31) -> 4 | D31: =+DAY(K31) -> 8 | E31: =IF(A31=C31,D31-B31+1,DAY(EOMONTH(I31,0))-B31+D31+1) -> 8 | F31: =1+F30 -> 14 | H31: =1+N30 -> 44291 | I31: =+H31+1 -> 44292 | J31: =+I31+1 -> 44293 | K31: =+J31+1 -> 44294 | L31: =+K31+1 -> 44295 | M31: =+L31+1 -> 44296 | N31: =+M31+1 -> 44297 | P31: =DATE(2021,C31,D31+1) -> 44295 | Q31: =IF(A31=C31,"Informe "&D31-B31+1&" días ( "&D31-B31&" reales y 1 proyectado); Reales del "&B31&"/"&C31&" al "&D31-1&"/"&A31&" ,Proyectado "&D31&"/"&A31,"Informe "&DAY(EOMONTH(K31,0))-B31+D31+1&" días ( "&DAY(EOMONTH(K31,0))-B31+D31&" reales y 1 proyectado); Reales del "&B31&"/"&A31&" al "&D31-1&"/"&C31&" ,Proyectado "&D31&"/"&C31) -> Informe 8 días ( 7 reales y 1 proyectado); Reales del 1/4 al 7/4 ,Proyectado 8/4 | R31: Sábado 03 de Abril: Sábado Santo
A32: =+MONTH(L31) -> 4 | B32: =+DAY(L31) -> 9 | C32: =+MONTH(K32) -> 4 | D32: =+DAY(K32) -> 15 | E32: =IF(A32=C32,D32-B32+1,DAY(EOMONTH(I32,0))-B32+D32+1) -> 7 | F32: =1+F31 -> 15 | H32: =1+N31 -> 44298 | I32: =+H32+1 -> 44299 | J32: =+I32+1 -> 44300 | K32: =+J32+1 -> 44301 | L32: =+K32+1 -> 44302 | M32: =+L32+1 -> 44303 | N32: =+M32+1 -> 44304 | P32: =DATE(2021,C32,D32+1) -> 44302 | Q32: =IF(A32=C32,"Informe "&D32-B32+1&" días ( "&D32-B32&" reales y 1 proyectado); Reales del "&B32&"/"&C32&" al "&D32-1&"/"&A32&" ,Proyectado "&D32&"/"&A32,"Informe "&DAY(EOMONTH(K32,0))-B32+D32+1&" días ( "&DAY(EOMONTH(K32,0))-B32+D32&" reales y 1 proyectado); Reales del "&B32&"/"&A32&" al "&D32-1&"/"&C32&" ,Proyectado "&D32&"/"&C32) -> Informe 7 días ( 6 reales y 1 proyectado); Reales del 9/4 al 14/4 ,Proyectado 15/4 | R32: Domingo 04 de Abril: Domingo de Resurrección
A33: =+MONTH(L32) -> 4 | B33: =+DAY(L32) -> 16 | C33: =+MONTH(K33) -> 4 | D33: =+DAY(K33) -> 22 | E33: =IF(A33=C33,D33-B33+1,DAY(EOMONTH(I33,0))-B33+D33+1) -> 7 | F33: =1+F32 -> 16 | H33: =1+N32 -> 44305 | I33: =+H33+1 -> 44306 | J33: =+I33+1 -> 44307 | K33: =+J33+1 -> 44308 | L33: =+K33+1 -> 44309 | M33: =+L33+1 -> 44310 | N33: =+M33+1 -> 44311 | P33: =DATE(2021,C33,D33+1) -> 44309 | Q33: =IF(A33=C33,"Informe "&D33-B33+1&" días ( "&D33-B33&" reales y 1 proyectado); Reales del "&B33&"/"&C33&" al "&D33-1&"/"&A33&" ,Proyectado "&D33&"/"&A33,"Informe "&DAY(EOMONTH(K33,0))-B33+D33+1&" días ( "&DAY(EOMONTH(K33,0))-B33+D33&" reales y 1 proyectado); Reales del "&B33&"/"&A33&" al "&D33-1&"/"&C33&" ,Proyectado "&D33&"/"&C33) -> Informe 7 días ( 6 reales y 1 proyectado); Reales del 16/4 al 21/4 ,Proyectado 22/4
A34: =+MONTH(L33) -> 4 | B34: =+DAY(L33) -> 23 | C34: =+MONTH(J34) -> 4 | D34: =+DAY(K34) -> 29 | E34: =IF(A34=C34,D34-B34+1,DAY(EOMONTH(I34,0))-B34+D34+1) -> 7 | F34: =1+F33 -> 17 | H34: =1+N33 -> 44312 | I34: =+H34+1 -> 44313 | J34: =+I34+1 -> 44314 | K34: 44315 | L34: 44316 | P34: =DATE(2021,C34,D34+1) -> 44316 | Q34: =IF(A34=C34,"Informe "&D34-B34+1&" días ( "&D34-B34&" reales y 1 proyectado); Reales del "&B34&"/"&C34&" al "&D34-1&"/"&A34&" ,Proyectado "&D34&"/"&A34,"Informe "&DAY(EOMONTH(K34,0))-B34+D34+1&" días ( "&DAY(EOMONTH(K34,0))-B34+D34&" reales y 1 proyectado); Reales del "&B34&"/"&A34&" al "&D34-1&"/"&C34&" ,Proyectado "&D34&"/"&C34) -> Informe 7 días ( 6 reales y 1 proyectado); Reales del 23/4 al 28/4 ,Proyectado 29/4
A36: desde | C36: hasta | E36: largo | F36: # week | H36: MAYO | P36: FECHA INFORME | Q36: DETALLES | R36: FERIADO
A37: m | B37: d | C37: m | D37: d | H37: L | I37: M | J37: M | K37: J | L37: V | M37: S | N37: D
M38: =+L34+1 -> 44317 | N38: =+M38+1 -> 44318 | R38: Sábado 1 de Mayo: Día del Trabajador
A39: =+MONTH(K34) -> 4 | B39: =+DAY(L34) -> 30 | C39: =+MONTH(K39) -> 5 | D39: =+DAY(K39) -> 6 | E39: =IF(A39=C39,D39-B39+1,DAY(EOMONTH(I34,0))-B39+D39+1) -> 7 | F39: =1+F34 -> 18 | H39: =1+N38 -> 44319 | I39: =+H39+1 -> 44320 | J39: =+I39+1 -> 44321 | K39: =+J39+1 -> 44322 | L39: =+K39+1 -> 44323 | M39: =+L39+1 -> 44324 | N39: =+M39+1 -> 44325 | P39: =DATE(2021,C39,D39+1) -> 44323 | Q39: =IF(A39=C39,"Informe "&D39-B39+1&" días ( "&D39-B39&" reales y 1 proyectado); Reales del "&B39&"/"&C39&" al "&D39-1&"/"&A39&" ,Proyectado "&D39&"/"&A39,"Informe "&DAY(EOMONTH(K33,0))-B39+D39+1&" días ( "&DAY(EOMONTH(K33,0))-B39+D39&" reales y 1 proyectado); Reales del "&B39&"/"&A39&" al "&D39-1&"/"&C39&" ,Proyectado "&D39&"/"&C39) -> Informe 7 días ( 6 reales y 1 proyectado); Reales del 30/4 al 5/5 ,Proyectado 6/5
A40: =+MONTH(L39) -> 5 | B40: =+DAY(L39) -> 7 | C40: =+MONTH(K40) -> 5 | D40: =+DAY(K40) -> 13 | E40: =IF(A40=C40,D40-B40+1,DAY(EOMONTH(I40,0))-B40+D40+1) -> 7 | F40: =1+F39 -> 19 | H40: =1+N39 -> 44326 | I40: =+H40+1 -> 44327 | J40: =+I40+1 -> 44328 | K40: =+J40+1 -> 44329 | L40: =+K40+1 -> 44330 | M40: =+L40+1 -> 44331 | N40: =+M40+1 -> 44332 | P40: =DATE(2021,C40,D40+1) -> 44330 | Q40: =IF(A40=C40,"Informe "&D40-B40+1&" días ( "&D40-B40&" reales y 1 proyectado); Reales del "&B40&"/"&C40&" al "&D40-1&"/"&A40&" ,Proyectado "&D40&"/"&A40,"Informe "&DAY(EOMONTH(K40,0))-B40+D40+1&" días ( "&DAY(EOMONTH(K40,0))-B40+D40&" reales y 1 proyectado); Reales del "&B40&"/"&A40&" al "&D40-1&"/"&C40&" ,Proyectado "&D40&"/"&C40) -> Informe 7 días ( 6 reales y 1 proyectado); Reales del 7/5 al 12/5 ,Proyectado 13/5
A41: =+MONTH(L40) -> 5 | B41: =+DAY(L40) -> 14 | C41: =+MONTH(K41) -> 5 | D41: =+DAY(J41) -> 19 | E41: =IF(A41=C41,D41-B41+1,DAY(EOMONTH(I41,0))-B41+D41+1) -> 6 | F41: =1+F40 -> 20 | H41: =1+N40 -> 44333 | I41: =+H41+1 -> 44334 | J41: =+I41+1 -> 44335 | K41: =+J41+1 -> 44336 | L41: =+K41+1 -> 44337 | M41: =+L41+1 -> 44338 | N41: =+M41+1 -> 44339 | P41: =DATE(2021,C41,D41+1) -> 44336 | Q41: =IF(A41=C41,"Informe "&D41-B41+1&" días ( "&D41-B41&" reales y 1 proyectado); Reales del "&B41&"/"&C41&" al "&D41-1&"/"&A41&" ,Proyectado "&D41&"/"&A41,"Informe "&DAY(EOMONTH(K41,0))-B41+D41+1&" días ( "&DAY(EOMONTH(K41,0))-B41+D41&" reales y 1 proyectado); Reales del "&B41&"/"&A41&" al "&D41-1&"/"&C41&" ,Proyectado "&D41&"/"&C41) -> Informe 6 días ( 5 reales y 1 proyectado); Reales del 14/5 al 18/5 ,Proyectado 19/5 | R41: Viernes 21 de Mayo: Día de las Glorias Navales
A42: =+MONTH(J41) -> 5 | B42: =+DAY(K41) -> 20 | C42: =+MONTH(K42) -> 5 | D42: =+DAY(K42) -> 27 | E42: =IF(A42=C42,D42-B42+1,DAY(EOMONTH(I42,0))-B42+D42+1) -> 8 | F42: =1+F41 -> 21 | H42: =1+N41 -> 44340 | I42: =+H42+1 -> 44341 | J42: =+I42+1 -> 44342 | K42: =+J42+1 -> 44343 | L42: =+K42+1 -> 44344 | M42: =+L42+1 -> 44345 | N42: =+M42+1 -> 44346 | P42: =DATE(2021,C42,D42+1) -> 44344 | Q42: =IF(A42=C42,"Informe "&D42-B42+1&" días ( "&D42-B42&" reales y 1 proyectado); Reales del "&B42&"/"&C42&" al "&D42-1&"/"&A42&" ,Proyectado "&D42&"/"&A42,"Informe "&DAY(EOMONTH(K42,0))-B42+D42+1&" días ( "&DAY(EOMONTH(K42,0))-B42+D42&" reales y 1 proyectado); Reales del "&B42&"/"&A42&" al "&D42-1&"/"&C42&" ,Proyectado "&D42&"/"&C42) -> Informe 8 días ( 7 reales y 1 proyectado); Reales del 20/5 al 26/5 ,Proyectado 27/5
H43: =1+N42 -> 44347
A45: desde | C45: hasta | E45: largo | F45: # week | H45: JUNIO | P45: FECHA INFORME | Q45: DETALLES | R45: FERIADO
A46: m | B46: d | C46: m | D46: d | H46: L | I46: M | J46: M | K46: J | L46: V | M46: S | N46: D
A47: =+MONTH(L42) -> 5 | B47: =+DAY(L42) -> 28 | C47: =+MONTH(K47) -> 6 | D47: =+DAY(K47) -> 3 | E47: =IF(A47=C47,D47-B47+1,DAY(EOMONTH(I41,0))-B47+D47+1) -> 7 | F47: =F42+1 -> 22 | I47: =+H43+1 -> 44348 | J47: =+I47+1 -> 44349 | K47: =+J47+1 -> 44350 | L47: =+K47+1 -> 44351 | M47: =+L47+1 -> 44352 | N47: =+M47+1 -> 44353 | P47: =DATE(2021,C47,D47+1) -> 44351 | Q47: =IF(A47=C47,"Informe "&D47-B47+1&" días ( "&D47-B47&" reales y 1 proyectado); Reales del "&B47&"/"&C47&" al "&D47-1&"/"&A47&" ,Proyectado "&D47&"/"&A47,"Informe "&DAY(EOMONTH(L42,0))-B47+D47+1&" días ( "&DAY(EOMONTH(L42,0))-B47+D47&" reales y 1 proyectado); Reales del "&B47&"/"&A47&" al "&D47-1&"/"&C47&" ,Proyectado "&D47&"/"&C47) -> Informe 7 días ( 6 reales y 1 proyectado); Reales del 28/5 al 2/6 ,Proyectado 3/6
...

Sheet Calendario 2026
A1: 2026 | I1: INFORME SEMANAL | T1: =TODAY() -> 46139
A2: CORTES | I2: =+"PROGRAMACION "&A1 -> PROGRAMACION 2026 | T2: versión 0.0
A4: desde | C4: hasta | E4: largo | F4: # week | I4: ENERO | Q4: FECHA INFORME | R4: N° SEMANA | S4: DETALLES | T4: FERIADO
A5: m | B5: d | C5: m | D5: d | I5: L | J5: M | K5: M | L5: J | M5: V | N5: S | O5: D
K6: 46022 | L6: 46023 | M6: =L6+1 -> 46024 | N6: =M6+1 -> 46025 | O6: =N6+1 -> 46026 | T6: Jueves 1 de Enero: Año Nuevo
A7: =+MONTH(K6) -> 12 | B7: =+DAY(K6) -> 31 | C7: =+MONTH(L7) -> 1 | D7: =+DAY(L7) -> 8 | E7: =IF(A7=C7,D7-B7+1,DAY(EOMONTH(J7,0))-B7+D7+1) -> 9 | F7: 52 | I7: =O6+1 -> 46027 | J7: =+I7+1 -> 46028 | K7: =+J7+1 -> 46029 | L7: =+K7+1 -> 46030 | M7: =+L7+1 -> 46031 | N7: =+M7+1 -> 46032 | O7: =+N7+1 -> 46033 | Q7: =DATE($A$1,C7,D7+1) -> 46031 | R7: 1 | S7: =IF(A7=C7,"Informe "&D7-B7+1&" días ( "&D7-B7&" reales y 1 proyectado); Reales del "&B7&"/"&C7&" al "&D7-1&"/"&A7&" ,Proyectado "&D7&"/"&A7,"Informe "&DAY(EOMONTH(K6,0))-B7+D7+1&" días ( "&DAY(EOMONTH(K6,0))-B7+D7&" reales y 1 proyectado); Reales del "&B7&"/"&A7&" al "&D7-1&"/"&C7&" ,Proyectado "&D7&"/"&C7) -> Informe 9 días ( 8 reales y 1 proyectado); Reales del 31/12 al 7/1 ,Proyectado 8/1
A8: =+MONTH(M7) -> 1 | B8: =+DAY(M7) -> 9 | C8: =+MONTH(L8) -> 1 | D8: =+DAY(L8) -> 15 | E8: =IF(A8=C8,D8-B8+1,DAY(EOMONTH(J8,0))-B8+D8+1) -> 7 | F8: 1 | I8: =1+O7 -> 46034 | J8: =1+I8 -> 46035 | K8: =1+J8 -> 46036 | L8: =1+K8 -> 46037 | M8: =1+L8 -> 46038 | N8: =1+M8 -> 46039 | O8: =1+N8 -> 46040 | Q8: =DATE($A$1,C8,D8+1) -> 46038 | R8: =R7+1 -> 2 | S8: =IF(A8=C8,"Informe "&D8-B8+1&" días ( "&D8-B8&" reales y 1 proyectado); Reales del "&B8&"/"&C8&" al "&D8-1&"/"&A8&" ,Proyectado "&D8&"/"&A8,"Informe "&DAY(EOMONTH(L7,0))-B8+D8+1&" días ( "&DAY(EOMONTH(L7,0))-B8+D8&" reales y 1 proyectado); Reales del "&B8&"/"&A8&" al "&D8-1&"/"&C8&" ,Proyectado "&D8&"/"&C8) -> Informe 7 días ( 6 reales y 1 proyectado); Reales del 9/1 al 14/1 ,Proyectado 15/1
A9: =+MONTH(M8) -> 1 | B9: =+DAY(M8) -> 16 | C9: =+MONTH(L9) -> 1 | D9: =+DAY(L9) -> 22 | E9: =IF(A9=C9,D9-B9+1,DAY(EOMONTH(J9,0))-B9+D9+1) -> 7 | F9: 2 | I9: =1+O8 -> 46041 | J9: =1+I9 -> 46042 | K9: =1+J9 -> 46043 | L9: =1+K9 -> 46044 | M9: =1+L9 -> 46045 | N9: =1+M9 -> 46046 | O9: =1+N9 -> 46047 | Q9: =DATE($A$1,C9,D9+1) -> 46045 | R9: =R8+1 -> 3 | S9: =IF(A9=C9,"Informe "&D9-B9+1&" días ( "&D9-B9&" reales y 1 proyectado); Reales del "&B9&"/"&C9&" al "&D9-1&"/"&A9&" ,Proyectado "&D9&"/"&A9,"Informe "&DAY(EOMONTH(L8,0))-B9+D9+1&" días ( "&DAY(EOMONTH(L8,0))-B9+D9&" reales y 1 proyectado); Reales del "&B9&"/"&A9&" al "&D9-1&"/"&C9&" ,Proyectado "&D9&"/"&C9) -> Informe 7 días ( 6 reales y 1 proyectado); Reales del 16/1 al 21/1 ,Proyectado 22/1
A10: =+MONTH(M9) -> 1 | B10: =+DAY(M9) -> 23 | C10: =+MONTH(L10) -> 1 | D10: =+DAY(L10) -> 29 | E10: =IF(A10=C10,D10-B10+1,DAY(EOMONTH(J10,0))-B10+D10+1) -> 7 | F10: 3 | I10: =1+O9 -> 46048 | J10: =1+I10 -> 46049 | K10: =1+J10 -> 46050 | L10: =1+K10 -> 46051 | M10: =1+L10 -> 46052 | N10: =1+M10 -> 46053 | Q10: =DATE($A$1,C10,D10+1) -> 46052 | R10: =R9+1 -> 4 | S10: =IF(A10=C10,"Informe "&D10-B10+1&" días ( "&D10-B10&" reales y 1 proyectado); Reales del "&B10&"/"&C10&" al "&D10-1&"/"&A10&" ,Proyectado "&D10&"/"&A10,"Informe "&DAY(EOMONTH(L9,0))-B10+D10+1&" días ( "&DAY(EOMONTH(L9,0))-B10+D10&" reales y 1 proyectado); Reales del "&B10&"/"&A10&" al "&D10-1&"/"&C10&" ,Proyectado "&D10&"/"&C10) -> Informe 7 días ( 6 reales y 1 proyectado); Reales del 23/1 al 28/1 ,Proyectado 29/1
A12: desde | C12: hasta | E12: largo | F12: # week | I12: FEBRERO | Q12: FECHA INFORME | R12: N° SEMANA | S12: DETALLES | T12: FERIADO
A13: m | B13: d | C13: m | D13: d | I13: L | J13: M | K13: M | L13: J | M13: V | N13: S | O13: D
F14: 5 | O14: =+N10+1 -> 46054
A15: =+MONTH(M10) -> 1 | B15: =+DAY(M10) -> 30 | C15: =+MONTH(L15) -> 2 | D15: =+DAY(L15) -> 5 | E15: =IF(A15=C15,D15-B15+1,DAY(EOMONTH(M10,0))-B15+D15+1) -> 7 | F15: =1+F14 -> 6 | I15: =1+O14 -> 46055 | J15: =+I15+1 -> 46056 | K15: =+J15+1 -> 46057 | L15: =+K15+1 -> 46058 | M15: =+L15+1 -> 46059 | N15: =+M15+1 -> 46060 | O15: =+N15+1 -> 46061 | Q15: =DATE($A$1,C15,D15+1) -> 46059 | R15: =R10+1 -> 5 | S15: =IF(A15=C15,"Informe "&D15-B15+1&" días ( "&D15-B15&" reales y 1 proyectado); Reales del "&B15&"/"&C15&" al "&D15-1&"/"&A15&" ,Proyectado "&D15&"/"&A15,"Informe "&DAY(EOMONTH(M14,0))-B15+D15+1&" días ( "&DAY(EOMONTH(M14,0))-B15+D15&" reales y 1 proyectado); Reales del "&B15&"/"&A15&" al "&D15-1&"/"&C15&" ,Proyectado "&D15&"/"&C15) -> Informe 7 días ( 6 reales y 1 proyectado); Reales del 30/1 al 4/2 ,Proyectado 5/2
A16: =+MONTH(M15) -> 2 | B16: =+DAY(M15) -> 6 | C16: =+MONTH(L16) -> 2 | D16: =+DAY(L16) -> 12 | E16: =IF(A16=C16,D16-B16+1,DAY(EOMONTH(M11,0))-B16+D16+1) -> 7 | F16: =1+F15 -> 7 | I16: =1+O15 -> 46062 | J16: =+I16+1 -> 46063 | K16: =+J16+1 -> 46064 | L16: =+K16+1 -> 46065 | M16: =+L16+1 -> 46066 | N16: =+M16+1 -> 46067 | O16: =+N16+1 -> 46068 | Q16: =DATE($A$1,C16,D16+1) -> 46066 | R16: =R15+1 -> 6 | S16: =IF(A16=C16,"Informe "&D16-B16+1&" días ( "&D16-B16&" reales y 1 proyectado); Reales del "&B16&"/"&C16&" al "&D16-1&"/"&A16&" ,Proyectado "&D16&"/"&A16,"Informe "&DAY(EOMONTH(L15,0))-B16+D16+1&" días ( "&DAY(EOMONTH(L15,0))-B16+D16&" reales y 1 proyectado); Reales del "&B16&"/"&A16&" al "&D16-1&"/"&C16&" ,Proyectado "&D16&"/"&C16&")") -> Informe 7 días ( 6 reales y 1 proyectado); Reales del 6/2 al 11/2 ,Proyectado 12/2
A17: =+MONTH(M16) -> 2 | B17: =+DAY(M16) -> 13 | C17: =+MONTH(L17) -> 2 | D17: =+DAY(L17) -> 19 | E17: =IF(A17=C17,D17-B17+1,DAY(EOMONTH(M12,0))-B17+D17+1) -> 7 | F17: =1+F16 -> 8 | I17: =1+O16 -> 46069 | J17: =+I17+1 -> 46070 | K17: =+J17+1 -> 46071 | L17: =+K17+1 -> 46072 | M17: =+L17+1 -> 46073 | N17: =+M17+1 -> 46074 | O17: =+N17+1 -> 46075 | Q17: =DATE($A$1,C17,D17+1) -> 46073 | R17: =R16+1 -> 7 | S17: =IF(A17=C17,"Informe "&D17-B17+1&" días ( "&D17-B17&" reales y 1 proyectado); Reales del "&B17&"/"&C17&" al "&D17-1&"/"&A17&" ,Proyectado "&D17&"/"&A17,"Informe "&DAY(EOMONTH(L16,0))-B17+D17+1&" días ( "&DAY(EOMONTH(L16,0))-B17+D17&" reales y 1 proyectado); Reales del "&B17&"/"&A17&" al "&D17-1&"/"&C17&" ,Proyectado "&D17&"/"&C17&")") -> Informe 7 días ( 6 reales y 1 proyectado); Reales del 13/2 al 18/2 ,Proyectado 19/2
A18: =+MONTH(M17) -> 2 | B18: =+DAY(M17) -> 20 | C18: =+MONTH(L18) -> 2 | D18: =+DAY(L18) -> 26 | E18: =IF(A18=C18,D18-B18+1,DAY(EOMONTH(M13,0))-B18+D18+1) -> 7 | F18: 9 | I18: =+O17+1 -> 46076 | J18: =+I18+1 -> 46077 | K18: =+J18+1 -> 46078 | L18: =+K18+1 -> 46079 | M18: =+L18+1 -> 46080 | N18: =+M18+1 -> 46081 | Q18: =DATE($A$1,C18,D18+1) -> 46080 | R18: =R17+1 -> 8 | S18: =IF(A18=C18,"Informe "&D18-B18+1&" días ( "&D18-B18&" reales y 1 proyectado); Reales del "&B18&"/"&C18&" al "&D18-1&"/"&A18&" ,Proyectado "&D18&"/"&A18,"Informe "&DAY(EOMONTH(L17,0))-B18+D18+1&" días ( "&DAY(EOMONTH(L17,0))-B18+D18&" reales y 1 proyectado); Reales del "&B18&"/"&A18&" al "&D18-1&"/"&C18&" ,Proyectado "&D18&"/"&C18&")") -> Informe 7 días ( 6 reales y 1 proyectado); Reales del 20/2 al 25/2 ,Proyectado 26/2
A20: desde | C20: hasta | E20: largo | F20: # week | I20: MARZO | Q20: FECHA INFORME | R20: N° SEMANA | S20: DETALLES | T20: FERIADO
A21: m | B21: d | C21: m | D21: d | I21: L | J21: M | K21: M | L21: J | M21: V | N21: S | O21: D
F22: =F17+1 -> 9 | K22: =+J18+1 -> 46078 | O22: =+N18+1 -> 46082
A23: =+MONTH(M18) -> 2 | B23: =+DAY(M18) -> 27 | C23: =+MONTH(L23) -> 3 | D23: =+DAY(L23) -> 5 | E23: =IF(A23=C23,D23-B23+1,DAY(EOMONTH(J23,0))-B23+D23+1) -> 10 | F23: =1+F22 -> 10 | I23: =1+O22 -> 46083 | J23: =+I23+1 -> 46084 | K23: =+J23+1 -> 46085 | L23: =+K23+1 -> 46086 | M23: =+L23+1 -> 46087 | N23: =+M23+1 -> 46088 | O23: =+N23+1 -> 46089 | Q23: =DATE($A$1,C23,D23+1) -> 46087 | R23: =R18+1 -> 9 | S23: =IF(A23=C23,"Informe "&D23-B23+1&" días ( "&D23-B23&" reales y 1 proyectado); Reales del "&B23&"/"&C23&" al "&D23-1&"/"&A23&" ,Proyectado "&D23&"/"&A23,"Informe "&DAY(EOMONTH(L18,0))-B23+D23+1&" días ( "&DAY(EOMONTH(L18,0))-B23+D23&" reales y 1 proyectado); Reales del "&B23&"/"&A23&" al "&D23-1&"/"&C23&" ,Proyectado "&D23&"/"&C23&")") -> Informe 7 días ( 6 reales y 1 proyectado); Reales del 27/2 al 4/3 ,Proyectado 5/3)
A24: =+MONTH(M23) -> 3 | B24: =+DAY(M23) -> 6 | C24: =+MONTH(L24) -> 3 | D24: =+DAY(L24) -> 12 | E24: =IF(A24=C24,D24-B24+1,DAY(EOMONTH(J24,0))-B24+D24+1) -> 7 | F24: =1+F23 -> 11 | I24: =1+O23 -> 46090 | J24: =+I24+1 -> 46091 | K24: =+J24+1 -> 46092 | L24: =+K24+1 -> 46093 | M24: =+L24+1 -> 46094 | N24: =+M24+1 -> 46095 | O24: =+N24+1 -> 46096 | Q24: =DATE($A$1,C24,D24+1) -> 46094 | R24: =R23+1 -> 10 | S24: =IF(A24=C24,"Informe "&D24-B24+1&" días ( "&D24-B24&" reales y 1 proyectado); Reales del "&B24&"/"&C24&" al "&D24-1&"/"&A24&" ,Proyectado "&D24&"/"&A24,"Informe "&DAY(EOMONTH(L23,0))-B24+D24+1&" días ( "&DAY(EOMONTH(L23,0))-B24+D24&" reales y 1 proyectado); Reales del "&B24&"/"&A24&" al "&D24-1&"/"&C24&" ,Proyectado "&D24&"/"&C24&")") -> Informe 7 días ( 6 reales y 1 proyectado); Reales del 6/3 al 11/3 ,Proyectado 12/3
A25: =+MONTH(M24) -> 3 | B25: =+DAY(M24) -> 13 | C25: =+MONTH(L25) -> 3 | D25: =+DAY(L25) -> 19 | E25: =IF(A25=C25,D25-B25+1,DAY(EOMONTH(J24,0))-B25+D25+1) -> 7 | F25: =1+F24 -> 12 | I25: =1+O24 -> 46097 | J25: =+I25+1 -> 46098 | K25: =+J25+1 -> 46099 | L25: =+K25+1 -> 46100 | M25: =+L25+1 -> 46101 | N25: =+M25+1 -> 46102 | O25: =+N25+1 -> 46103 | Q25: =DATE($A$1,C25,D25+1) -> 46101 | R25: =R24+1 -> 11 | S25: =IF(A25=C25,"Informe "&D25-B25+1&" días ( "&D25-B25&" reales y 1 proyectado); Reales del "&B25&"/"&C25&" al "&D25-1&"/"&A25&" ,Proyectado "&D25&"/"&A25,"Informe "&DAY(EOMONTH(L24,0))-B25+D25+1&" días ( "&DAY(EOMONTH(L24,0))-B25+D25&" reales y 1 proyectado); Reales del "&B25&"/"&A25&" al "&D25-1&"/"&C25&" ,Proyectado "&D25&"/"&C25&")") -> Informe 7 días ( 6 reales y 1 proyectado); Reales del 13/3 al 18/3 ,Proyectado 19/3
A26: =+MONTH(M25) -> 3 | B26: =+DAY(M25) -> 20 | C26: =+MONTH(L26) -> 3 | D26: =+DAY(L26) -> 26 | E26: =IF(A26=C26,D26-B26+1,DAY(EOMONTH(J25,0))-B26+D26+1) -> 7 | F26: =1+F25 -> 13 | I26: =1+O25 -> 46104 | J26: =+I26+1 -> 46105 | K26: =+J26+1 -> 46106 | L26: =+K26+1 -> 46107 | M26: =+L26+1 -> 46108 | N26: =+M26+1 -> 46109 | O26: =+N26+1 -> 46110 | Q26: =DATE($A$1,C26,D26+1) -> 46108 | R26: =R25+1 -> 12 | S26: =IF(A26=C26,"Informe "&D26-B26+1&" días ( "&D26-B26&" reales y 1 proyectado); Reales del "&B26&"/"&C26&" al "&D26-1&"/"&A26&" ,Proyectado "&D26&"/"&A26,"Informe "&DAY(EOMONTH(L25,0))-B26+D26+1&" días ( "&DAY(EOMONTH(L25,0))-B26+D26&" reales y 1 proyectado); Reales del "&B26&"/"&A26&" al "&D26-1&"/"&C26&" ,Proyectado "&D26&"/"&C26&")") -> Informe 7 días ( 6 reales y 1 proyectado); Reales del 20/3 al 25/3 ,Proyectado 26/3
I27: =+O26+1 -> 46111 | J27: =+I27+1 -> 46112
A29: desde | C29: hasta | E29: largo | F29: # week | I29: ABRIL | Q29: FECHA INFORME | R29: N° SEMANA | S29: DETALLES | T29: FERIADO
A30: m | B30: d | C30: m | D30: d | I30: L | J30: M | K30: M | L30: J | M30: V | N30: S | O30: D
A31: =+MONTH(M26) -> 3 | B31: =+DAY(M26) -> 27 | C31: =+MONTH(L31) -> 4 | D31: =+DAY(K31) -> 1 | E31: =IF(A31=C31,D31-B31+1,DAY(EOMONTH(L26,0))-B31+D31+1) -> 6 | F31: 13 | K31: =+J27+1 -> 46113 | L31: =+K31+1 -> 46114 | M31: =+L31+1 -> 46115 | N31: =+M31+1 -> 46116 | O31: =+N31+1 -> 46117 | Q31: =DATE($A$1,C31,D31+1) -> 46114 | R31: =R26+1 -> 13 | S31: =IF(A31=C31,"Informe "&D31-B31+1&" días ( "&D31-B31&" reales y 1 proyectado); Reales del "&B31&"/"&C31&" al "&D31-1&"/"&A31&" ,Proyectado "&D31&"/"&A31,"Informe "&DAY(EOMONTH(M26,0))-B31+D31+1&" días ( "&DAY(EOMONTH(M26,0))-B31+D31&" reales y 1 proyectado); Reales del "&B31&"/"&A31&" al 31/"&C31&" ,Proyectado "&D31&"/"&C31&")") -> Informe 6 días ( 5 reales y 1 proyectado); Reales del 27/3 al 31/4 ,Proyectado 1/4) | T31: Viernes 3 de abril: Viernes Santo Sábado 4 de abril: Sábado Santo
A32: =+MONTH(L31) -> 4 | B32: =+DAY(L31) -> 2 | C32: =+MONTH(L32) -> 4 | D32: =+DAY(L32) -> 9 | E32: =IF(A32=C32,D32-B32+1,DAY(EOMONTH(J32,0))-B32+D32+1) -> 8 | F32: =1+F31 -> 14 | I32: =1+O31 -> 46118 | J32: =+I32+1 -> 46119 | K32: =+J32+1 -> 46120 | L32: =+K32+1 -> 46121 | M32: =+L32+1 -> 46122 | N32: =+M32+1 -> 46123 | O32: =+N32+1 -> 46124 | Q32: =DATE($A$1,C32,D32+1) -> 46122 | R32: =+R31+1 -> 14 | S32: =IF(A32=C32,"Informe "&D32-B32+1&" días ( "&D32-B32&" reales y 1 proyectado); Reales del "&B32&"/"&C32&" al "&D32-1&"/"&A32&" ,Proyectado "&D32&"/"&A32,"Informe "&DAY(EOMONTH(L31,0))-B32+D32+1&" días ( "&DAY(EOMONTH(L31,0))-B32+D32&" reales y 1 proyectado); Reales del "&B32&"/"&A32&" al "&D32-1&"/"&C32&" ,Proyectado "&D32&"/"&C32&")") -> Informe 8 días ( 7 reales y 1 proyectado); Reales del 2/4 al 8/4 ,Proyectado 9/4
A33: =+MONTH(M32) -> 4 | B33: =+DAY(M32) -> 10 | C33: =+MONTH(L33) -> 4 | D33: =+DAY(L33) -> 16 | E33: =IF(A33=C33,D33-B33+1,DAY(EOMONTH(J33,0))-B33+D33+1) -> 7 | F33: =1+F32 -> 15 | I33: =1+O32 -> 46125 | J33: =+I33+1 -> 46126 | K33: =+J33+1 -> 46127 | L33: =+K33+1 -> 46128 | M33: =+L33+1 -> 46129 | N33: =+M33+1 -> 46130 | O33: =+N33+1 -> 46131 | Q33: =DATE($A$1,C33,D33+1) -> 46129 | R33: =R32+1 -> 15 | S33: =IF(A33=C33,"Informe "&D33-B33+1&" días ( "&D33-B33&" reales y 1 proyectado); Reales del "&B33&"/"&C33&" al "&D33-1&"/"&A33&" ,Proyectado "&D33&"/"&A33,"Informe "&DAY(EOMONTH(L32,0))-B33+D33+1&" días ( "&DAY(EOMONTH(L32,0))-B33+D33&" reales y 1 proyectado); Reales del "&B33&"/"&A33&" al "&D33-1&"/"&C33&" ,Proyectado "&D33&"/"&C33&")") -> Informe 7 días ( 6 reales y 1 proyectado); Reales del 10/4 al 15/4 ,Proyectado 16/4
A34: =+MONTH(M33) -> 4 | B34: =+DAY(M33) -> 17 | C34: =+MONTH(L34) -> 4 | D34: =+DAY(L34) -> 23 | E34: =IF(A34=C34,D34-B34+1,DAY(EOMONTH(J34,0))-B34+D34+1) -> 7 | F34: =1+F33 -> 16 | I34: =1+O33 -> 46132 | J34: =+I34+1 -> 46133 | K34: =+J34+1 -> 46134 | L34: =+K34+1 -> 46135 | M34: =+L34+1 -> 46136 | N34: =+M34+1 -> 46137 | O34: =+N34+1 -> 46138 | Q34: =DATE($A$1,C34,D34+1) -> 46136 | R34: =R33+1 -> 16 | S34: =IF(A34=C34,"Informe "&D34-B34+1&" días ( "&D34-B34&" reales y 1 proyectado); Reales del "&B34&"/"&C34&" al "&D34-1&"/"&A34&" ,Proyectado "&D34&"/"&A34,"Informe "&DAY(EOMONTH(L33,0))-B34+D34+1&" días ( "&DAY(EOMONTH(L33,0))-B34+D34&" reales y 1 proyectado); Reales del "&B34&"/"&A34&" al "&D34-1&"/"&C34&" ,Proyectado "&D34&"/"&C34&")") -> Informe 7 días ( 6 reales y 1 proyectado); Reales del 17/4 al 22/4 ,Proyectado 23/4
A35: =+MONTH(M34) -> 4 | B35: =+DAY(M34) -> 24 | C35: =+MONTH(K35) -> 4 | D35: =+DAY(K35) -> 29 | F35: =1+F34 -> 17 | I35: =1+O34 -> 46139 | J35: =+I35+1 -> 46140 | K35: =+J35+1 -> 46141 | L35: =+K35+1 -> 46142 | Q35: =DATE($A$1,C35,D35+1) -> 46142 | R35: =R34+1 -> 17 | S35: =IF(A35=C35,"Informe "&D35-B35+1&" días ( "&D35-B35&" reales y 1 proyectado); Reales del "&B35&"/"&C35&" al "&D35-1&"/"&A35&" ,Proyectado "&D35&"/"&A35,"Informe "&DAY(EOMONTH(L34,0))-B35+D35+1&" días ( "&DAY(EOMONTH(L34,0))-B35+D35&" reales y 1 proyectado); Reales del "&B35&"/"&A35&" al "&D35-1&"/"&C35&" ,Proyectado "&D35&"/"&C35&")") -> Informe 6 días ( 5 reales y 1 proyectado); Reales del 24/4 al 28/4 ,Proyectado 29/4
A37: desde | C37: hasta | E37: largo | F37: # week | I37: MAYO | Q37: FECHA INFORME | R37: N° SEMANA | S37: DETALLES | T37: FERIADO
A38: m | B38: d | C38: m | D38: d | I38: L | J38: M | K38: M | L38: J | M38: V | N38: S | O38: D
E39: =IF(A39=C39,D39-B39+1,DAY(EOMONTH(J34,0))-B39+D39+1) -> 1 | F39: =+F35+1 -> 18 | K39: 45413 | M39: =+L35+1 -> 46143 | N39: =+M39+1 -> 46144 | O39: =+N39+1 -> 46145 | T39: Viernes 1 de mayo: Día del Trabajador
A40: =+MONTH(L35) -> 4 | B40: =+DAY(L35) -> 30 | C40: =+MONTH(L40) -> 5 | D40: =+DAY(L40) -> 7 | E40: =IF(A40=C40,D40-B40+1,DAY(EOMONTH(J35,0))-B40+D40+1) -> 8 | F40: =+F39+1 -> 19 | I40: =1+O39 -> 46146 | J40: =+I40+1 -> 46147 | K40: =+J40+1 -> 46148 | L40: =+K40+1 -> 46149 | M40: =+L40+1 -> 46150 | N40: =+M40+1 -> 46151 | O40: =+N40+1 -> 46152 | Q40: =DATE($A$1,C40,D40+1) -> 46150 | R40: =R35+1 -> 18 | S40: =IF(A40=C40,"Informe "&D40-B40+1&" días ( "&D40-B40&" reales y 1 proyectado); Reales del "&B40&"/"&C40&" al "&D40-1&"/"&A40&" ,Proyectado "&D40&"/"&A40,"Informe "&DAY(EOMONTH(L34,0))-B40+D40+1&" días ( "&DAY(EOMONTH(L34,0))-B40+D40&" reales y 1 proyectado); Reales del "&B40&"/"&A40&" al "&D40-1&"/"&C40&" ,Proyectado "&D40&"/"&C40) -> Informe 8 días ( 7 reales y 1 proyectado); Reales del 30/4 al 6/5 ,Proyectado 7/5
A41: =+MONTH(M40) -> 5 | B41: =+DAY(M40) -> 8 | C41: =+MONTH(L41) -> 5 | D41: =+DAY(L41) -> 14 | E41: =IF(A41=C41,D41-B41+1,DAY(EOMONTH(J41,0))-B41+D41+1) -> 7 | F41: =1+F40 -> 20 | I41: =1+O40 -> 46153 | J41: =+I41+1 -> 46154 | K41: =+J41+1 -> 46155 | L41: =+K41+1 -> 46156 | M41: =+L41+1 -> 46157 | N41: =+M41+1 -> 46158 | O41: =+N41+1 -> 46159 | Q41: =DATE($A$1,C41,D41+1) -> 46157 | R41: =R40+1 -> 19 | S41: =IF(A41=C41,"Informe "&D41-B41+1&" días ( "&D41-B41&" reales y 1 proyectado); Reales del "&B41&"/"&C41&" al "&D41-1&"/"&A41&" ,Proyectado "&D41&"/"&A41,"Informe "&DAY(EOMONTH(L41,0))-B41+D41+1&" días ( "&DAY(EOMONTH(L41,0))-B41+D41&" reales y 1 proyectado); Reales del "&B41&"/"&A41&" al "&D41-1&"/"&C41&" ,Proyectado "&D41&"/"&C41) -> Informe 7 días ( 6 reales y 1 proyectado); Reales del 8/5 al 13/5 ,Proyectado 14/5
A42: =+MONTH(M41) -> 5 | B42: =+DAY(M41) -> 15 | C42: =+MONTH(L42) -> 5 | D42: =+DAY(J42) -> 19 | E42: =IF(A42=C42,D42-B42+1,DAY(EOMONTH(J42,0))-B42+D42+1) -> 5 | F42: =1+F41 -> 21 | I42: =1+O41 -> 46160 | J42: =+I42+1 -> 46161 | K42: =+J42+1 -> 46162 | L42: =+K42+1 -> 46163 | M42: =+L42+1 -> 46164 | N42: =+M42+1 -> 46165 | O42: =+N42+1 -> 46166 | Q42: =DATE($A$1,C42,D42+1) -> 46162 | R42: =R41+1 -> 20 | S42: =IF(A42=C42,"Informe "&D42-B42+1&" días ( "&D42-B42&" reales y 1 proyectado); Reales del "&B42&"/"&C42&" al "&D42-1&"/"&A42&" ,Proyectado "&D42&"/"&A42,"Informe "&DAY(EOMONTH(J42,0))-B42+D42+1&" días ( "&DAY(EOMONTH(J42,0))-B42+D42&" reales y 1 proyectado); Reales del "&B42&"/"&A42&" al "&D42-1&"/"&C42&" ,Proyectado "&D42&"/"&C42) -> Informe 5 días ( 4 reales y 1 proyectado); Reales del 15/5 al 18/5 ,Proyectado 19/5 | T42: Jueves 21 de mayo: Día de las Glorias Navales. Viernes 22 de mayo interferiado.
A43: =+MONTH(M42) -> 5 | B43: =+DAY(K42) -> 20 | C43: =+MONTH(L43) -> 5 | D43: =+DAY(L43) -> 28 | E43: =IF(A43=C43,D43-B43+1,DAY(EOMONTH(J43,0))-B43+D43+1) -> 9 | F43: =+F42+1 -> 22 | I43: =1+O42 -> 46167 | J43: =+I43+1 -> 46168 | K43: =+J43+1 -> 46169 | L43: =+K43+1 -> 46170 | M43: =+L43+1 -> 46171 | N43: =+M43+1 -> 46172 | O43: =+N43+1 -> 46173 | Q43: =DATE($A$1,C43,D43+1) -> 46171 | R43: =R42+1 -> 21 | S43: =IF(A43=C43,"Informe "&D43-B43+1&" días ( "&D43-B43&" reales y 1 proyectado); Reales del "&B43&"/"&C43&" al "&D43-1&"/"&A43&" ,Proyectado "&D43&"/"&A43,"Informe "&DAY(EOMONTH(L43,0))-B43+D43+1&" días ( "&DAY(EOMONTH(L43,0))-B43+D43&" reales y 1 proyectado); Reales del "&B43&"/"&A43&" al "&D43-1&"/"&C43&" ,Proyectado "&D43&"/"&C43) -> Informe 9 días ( 8 reales y 1 proyectado); Reales del 20/5 al 27/5 ,Proyectado 28/5
A45: desde | C45: hasta | E45: largo | F45: # week | I45: JUNIO | Q45: FECHA INFORME | R45: N° SEMANA | S45: DETALLES | T45: FERIADO
A46: m | B46: d | C46: m | D46: d | I46: L | J46: M | K46: M | L46: J | M46: V | N46: S | O46: D
...

Sheet Programación
F1: Mes | G1: Abril
A2: Mes | B2: Week | C2: dia reporte | D2: Responsable
A3: Enero | B3: 1 | C3: =VLOOKUP(B3,'calendario 2021'!F5:P166,11,0) -> 44204 | D3: Victor | F3: Cuenta de Responsable
A4: Enero | B4: 2 | C4: =VLOOKUP(B4,'calendario 2021'!F6:P167,11,0) -> 44211 | D4: Victor | F4: Week | G4: dia reporte | H4: Responsable | I4: Total
A5: Enero | B5: 3 | C5: =VLOOKUP(B5,'calendario 2021'!F7:P168,11,0) -> 44218 | D5: Victor | F5: 15 | G5: 09-abr | H5: Victor | I5: 1
A6: Enero | B6: 4 | C6: =VLOOKUP(B6,'calendario 2021'!F8:P169,11,0) -> 44225 | D6: Josefina | F6: 16 | G6: 17-abr | H6: Josefina | I6: 1
A7: Enero | B7: 5 | C7: =VLOOKUP(B7,'calendario 2021'!F9:P170,11,0) -> 44232 | D7: Josefina | F7: 17 | G7: 24-abr | H7: Josefina | I7: 1
A8: Febrero | B8: 6 | C8: =VLOOKUP(B8,'calendario 2021'!F10:P171,11,0) -> 44239 | D8: Josefina | F8: 18 | G8: 30-abr | H8: Josefina | I8: 1
A9: Febrero | B9: 7 | C9: =VLOOKUP(B9,'calendario 2021'!F11:P172,11,0) -> 44246 | D9: Iván | F9: Total general | I9: 4
A10: Febrero | B10: 8 | C10: =VLOOKUP(B10,'calendario 2021'!F12:P173,11,0) -> 44253 | D10: Iván
A11: Febrero | B11: 9 | C11: =VLOOKUP(B11,'calendario 2021'!F13:P174,11,0) -> 44260 | D11: Iván
A12: Marzo | B12: 10 | C12: =VLOOKUP(B12,'calendario 2021'!F14:P175,11,0) -> 44267 | D12: Manuel
A13: Marzo | B13: 11 | C13: =VLOOKUP(B13,'calendario 2021'!F15:P176,11,0) -> 44274 | D13: Manuel
A14: Marzo | B14: 12 | C14: =VLOOKUP(B14,'calendario 2021'!F16:P177,11,0) -> 44281 | D14: Manuel
A15: Marzo | B15: 13 | C15: =VLOOKUP(B15,'calendario 2021'!F17:P178,11,0) -> 44287 | D15: Victor
A16: Marzo | B16: 14 | C16: =VLOOKUP(B16,'calendario 2021'!F18:P179,11,0) -> 44295 | D16: Victor
A17: Abril | B17: 15 | C17: =VLOOKUP(B17,'calendario 2021'!F18:P180,11,0) -> 44302 | D17: Victor
A18: Abril | B18: 16 | C18: =VLOOKUP(B18,'calendario 2021'!F19:P181,11,0) -> 44309 | D18: Josefina
A19: Abril | B19: 17 | C19: =VLOOKUP(B19,'calendario 2021'!F20:P182,11,0) -> 44316 | D19: Josefina
A20: Abril | B20: 18 | C20: =VLOOKUP(B20,'calendario 2021'!F21:P183,11,0) -> 44323 | D20: Josefina
A21: Mayo | B21: 19 | C21: =VLOOKUP(B21,'calendario 2021'!F22:P184,11,0) -> 44330 | D21: Iván
A22: Mayo | B22: 20 | C22: =VLOOKUP(B22,'calendario 2021'!F23:P185,11,0) -> 44336 | D22: Iván
A23: Mayo | B23: 21 | C23: =VLOOKUP(B23,'calendario 2021'!F24:P186,11,0) -> 44344 | D23: Iván
A24: Mayo | B24: 22 | C24: =VLOOKUP(B24,'calendario 2021'!F25:P187,11,0) -> 44351 | D24: Manuel
A25: Junio | B25: 23 | C25: =VLOOKUP(B25,'calendario 2021'!F26:P188,11,0) -> 44358 | D25: Manuel
A26: Junio | B26: 24 | C26: =VLOOKUP(B26,'calendario 2021'!F27:P189,11,0) -> 44365 | D26: Manuel
A27: Junio | B27: 25 | C27: =VLOOKUP(B27,'calendario 2021'!F28:P190,11,0) -> 44372 | D27: Victor
A28: Junio | B28: 26 | C28: =VLOOKUP(B28,'calendario 2021'!F29:P191,11,0) -> 0 | D28: Victor
... A41: Septiembre | B41: 39 | C41: =VLOOKUP(B41,'calendario 2021'!F42:P204,11,0) -> 0 | D41: Victor
A42: Septiembre | B42: 40 | C42: =VLOOKUP(B42,'calendario 2021'!F44:P205,11,0) -> 44477 | D42: Josefina
A43: Octubre | B43: 41 | C43: =VLOOKUP(B43,'calendario 2021'!F45:P206,11,0) -> 44484 | D43: Josefina
A44: Octubre | B44: 42 | C44: =VLOOKUP(B44,'calendario 2021'!F46:P207,11,0) -> 44491 | D44: Josefina
A45: Octubre | B45: 43 | C45: =VLOOKUP(B45,'calendario 2021'!F47:P208,11,0) -> 44498 | D45: Iván
A46: Octubre | B46: 44 | C46: =VLOOKUP(B46,'calendario 2021'!F48:P209,11,0) -> 44505 | D46: Iván
A47: Noviembre | B47: 45 | C47: =VLOOKUP(B47,'calendario 2021'!F49:P210,11,0) -> 44512 | D47: Iván
A48: Noviembre | B48: 46 | C48: =VLOOKUP(B48,'calendario 2021'!F50:P211,11,0) -> 44519 | D48: Manuel
A49: Noviembre | B49: 47 | C49: =VLOOKUP(B49,'calendario 2021'!F51:P212,11,0) -> 44526 | D49: Manuel
A50: Noviembre | B50: 48 | C50: =VLOOKUP(B50,'calendario 2021'!F52:P213,11,0) -> 0 | D50: Manuel
A51: Noviembre | B51: 49 | C51: =VLOOKUP(B51,'calendario 2021'!F56:P214,11,0) -> 44540 | D51: Victor
A52: Diciembre | B52: 50 | C52: =VLOOKUP(B52,'calendario 2021'!F57:P215,11,0) -> 44547 | D52: Victor
...
